<?xml version="1.0"?>
<robot name="agribot" xmlns:xacro="http://www.ros.org/wiki/xacro">

  <!-- Materials -->
  <material name="grey"><color rgba="0.5 0.5 0.5 1.0"/></material>
  <material name="black"><color rgba="0.1 0.1 0.1 1.0"/></material>

  <!-- Base Link: High-clearance chassis at 450mm -->
  <!-- Industrial scale: 0.9m x 0.6m heavy steel frame that fills space between wheels -->
  <link name="base_link">
    <visual>
      <origin xyz="0 0 0.45" rpy="0 0 0"/>
      <geometry>
        <box size="0.9 0.6 0.08"/> 
      </geometry>
      <material name="grey"/>
    </visual>
    <collision>
      <origin xyz="0 0 0.45" rpy="0 0 0"/>
      <geometry>
        <box size="0.9 0.6 0.08"/>
      </geometry>
    </collision>
    <inertial>
      <mass value="60.0"/>
      <origin xyz="0 0 0.45" rpy="0 0 0"/>
      <inertia ixx="1.5" ixy="0" ixz="0" iyy="2.0" iyz="0" izz="2.0"/>
    </inertial>
  </link>

  <!-- V-Leg Macro: Creates leg and wheel assembly -->
  <!-- Industrial scale: Heavy frame with V-legs that extend to wheels -->
  <!-- Corrected dimensions: 81cm (0.81m) wheelbase, 87cm (0.87m) track -->
  <xacro:macro name="v_leg" params="prefix x_reflect y_reflect">
    <!-- Leg Link: Thick square tubing (60mm) with sharper V-angle -->
    <link name="${prefix}_leg">
      <visual>
        <origin xyz="0 0 -0.12" rpy="0 ${x_reflect * 0.5} 0"/>
        <geometry><box size="0.06 0.06 0.35"/></geometry>
        <material name="grey"/>
      </visual>
      <collision>
        <origin xyz="0 0 -0.12" rpy="0 ${x_reflect * 0.5} 0"/>
        <geometry><box size="0.06 0.06 0.35"/></geometry>
      </collision>
      <inertial>
        <mass value="3.0"/>
        <origin xyz="0 0 -0.12"/>
        <inertia ixx="0.02" ixy="0" ixz="0" iyy="0.02" iyz="0" izz="0.02"/>
      </inertial>
    </link>

    <!-- Fixed joint connecting leg to base at chassis corners -->
    <joint name="${prefix}_leg_joint" type="fixed">
      <parent link="base_link"/>
      <child link="${prefix}_leg"/>
      <origin xyz="${x_reflect*0.4} ${y_reflect*0.3} 0.45" rpy="0 0 0"/>
    </joint>

    <!-- Wheel Link: 4.00-8 tire (405mm diameter, 0.2025m radius) -->
    <link name="${prefix}_wheel">
      <visual>
        <geometry><cylinder radius="0.2025" length="0.12"/></geometry>
        <material name="black"/>
      </visual>
      <collision>
        <geometry><cylinder radius="0.2025" length="0.12"/></geometry>
      </collision>
      <inertial>
        <mass value="8.0"/>
        <inertia ixx="0.1" ixy="0" ixz="0" iyy="0.1" iyz="0" izz="0.15"/>
      </inertial>
    </link>

    <!-- Continuous joint for wheel rotation -->
    <!-- Wheel offset: 0.3m leg attachment + 0.135m wheel offset = 0.435m (half of 0.87m track) -->
    <joint name="${prefix}_wheel_joint" type="continuous">
      <parent link="${prefix}_leg"/>
      <child link="${prefix}_wheel"/>
      <origin xyz="${x_reflect*0.08} ${y_reflect*0.135} -0.2475" rpy="${-pi/2} 0 0"/>
      <axis xyz="0 0 1"/>
      <limit effort="300" velocity="10.0"/>
    </joint>
    
    <!-- Gazebo friction parameters for skid-steer -->
    <gazebo reference="${prefix}_wheel">
      <mu1>1.1</mu1>
      <mu2>0.5</mu2>
      <kp>1000000.0</kp>
      <kd>10.0</kd>
    </gazebo>
  </xacro:macro>

  <!-- Instantiate 4 V-legs: front_left, front_right, rear_left, rear_right -->
  <xacro:v_leg prefix="front_left"  x_reflect="1"  y_reflect="1" />
  <xacro:v_leg prefix="front_right" x_reflect="1"  y_reflect="-1" />
  <xacro:v_leg prefix="rear_left"   x_reflect="-1" y_reflect="1" />
  <xacro:v_leg prefix="rear_right"  x_reflect="-1" y_reflect="-1" />

  <!-- Gazebo plugin for skid steer control -->
  <!-- Using diff_drive plugin with front wheels as primary control -->
  <!-- Rear wheels will follow via physics coupling -->
  <gazebo>
    <plugin name="differential_drive_controller" filename="libgazebo_ros_diff_drive.so">
      <update_rate>100</update_rate>
      <robotNamespace>/</robotNamespace>
      <left_joint>front_left_wheel_joint</left_joint>
      <right_joint>front_right_wheel_joint</right_joint>
      <wheel_separation>0.87</wheel_separation>
      <wheel_diameter>0.405</wheel_diameter>
      <max_wheel_torque>300</max_wheel_torque>
      <command_topic>cmd_vel</command_topic>
      <odometry_topic>odom</odometry_topic>
      <odometry_frame>odom</odometry_frame>
      <robot_base_frame>base_link</robot_base_frame>
      <publish_odom_tf>true</publish_odom_tf>
    </plugin>
  </gazebo>
  
  <!-- Sync rear wheels with front wheels for proper skid steer -->
  <gazebo reference="rear_left_wheel_joint">
    <implicitSpringDamper>true</implicitSpringDamper>
  </gazebo>
  <gazebo reference="rear_right_wheel_joint">
    <implicitSpringDamper>true</implicitSpringDamper>
  </gazebo>

</robot>
